Traceback (most recent call last):
  File "/Users/johnbutler/opt/anaconda3/lib/python3.8/site-packages/jupyter_cache/executors/utils.py", line 51, in single_nb_execution
    executenb(
  File "/Users/johnbutler/opt/anaconda3/lib/python3.8/site-packages/nbclient/client.py", line 1112, in execute
    return NotebookClient(nb=nb, resources=resources, km=km, **kwargs).execute()
  File "/Users/johnbutler/opt/anaconda3/lib/python3.8/site-packages/nbclient/util.py", line 74, in wrapped
    return just_run(coro(*args, **kwargs))
  File "/Users/johnbutler/opt/anaconda3/lib/python3.8/site-packages/nbclient/util.py", line 53, in just_run
    return loop.run_until_complete(coro)
  File "/Users/johnbutler/opt/anaconda3/lib/python3.8/asyncio/base_events.py", line 616, in run_until_complete
    return future.result()
  File "/Users/johnbutler/opt/anaconda3/lib/python3.8/site-packages/nbclient/client.py", line 553, in async_execute
    await self.async_execute_cell(
  File "/Users/johnbutler/opt/anaconda3/lib/python3.8/site-packages/nbclient/client.py", line 857, in async_execute_cell
    self._check_raise_for_error(cell, exec_reply)
  File "/Users/johnbutler/opt/anaconda3/lib/python3.8/site-packages/nbclient/client.py", line 760, in _check_raise_for_error
    raise CellExecutionError.from_cell_and_msg(cell, exec_reply_content)
nbclient.exceptions.CellExecutionError: An error occurred while executing the following cell:
------------------

d = {'time t_i': t,    'Euler (w_i) ':w,    'Taylor (w_i) ':y,    'Exact Error( |y_i-w_i|) ':np.abs(y-w)}
df = pd.DataFrame(data=d)
df
------------------

[0;31m---------------------------------------------------------------------------[0m
[0;31mNameError[0m                                 Traceback (most recent call last)
[0;32m<ipython-input-5-db90f40f54b9>[0m in [0;36m<module>[0;34m[0m
[0;32m----> 1[0;31m [0md[0m [0;34m=[0m [0;34m{[0m[0;34m'time t_i'[0m[0;34m:[0m [0mt[0m[0;34m,[0m    [0;34m'Euler (w_i) '[0m[0;34m:[0m[0mw[0m[0;34m,[0m    [0;34m'Taylor (w_i) '[0m[0;34m:[0m[0my[0m[0;34m,[0m    [0;34m'Exact Error( |y_i-w_i|) '[0m[0;34m:[0m[0mnp[0m[0;34m.[0m[0mabs[0m[0;34m([0m[0my[0m[0;34m-[0m[0mw[0m[0;34m)[0m[0;34m}[0m[0;34m[0m[0;34m[0m[0m
[0m[1;32m      2[0m [0mdf[0m [0;34m=[0m [0mpd[0m[0;34m.[0m[0mDataFrame[0m[0;34m([0m[0mdata[0m[0;34m=[0m[0md[0m[0;34m)[0m[0;34m[0m[0;34m[0m[0m
[1;32m      3[0m [0mdf[0m[0;34m[0m[0;34m[0m[0m

[0;31mNameError[0m: name 'y' is not defined
NameError: name 'y' is not defined

